Workbook

Sheet README
A1: Classeur Excel – Exploitation des questionnaires (données simulées)
A2: Voici un classeur Excel complet (données simulées + formules) qui reproduit les principaux tableaux d’exploitation qu’on peut générer à partir du questionnaire (rubriques 1 à 13) et de la logique décrite dans le rapport méthodologique.
A4: Objectif : illustrer les tableaux et traitements (avec formules) générés à partir du questionnaire (13 rubriques).
A5: Les feuilles 'Réponses_*' contiennent des données simulées. Les feuilles 'Analyse_*' et 'Synthèse_*' sont calculées par formules.
A7: Mode d’emploi (résumé) :
A8: 1) Remplacer les données simulées par les réponses réelles (mêmes colonnes).
A9: 2) Vérifier/ajuster les paramètres de codage et les pondérations (feuille Paramètres).
A10: 3) Consulter les analyses (classements domaines/indicateurs) et synthèses (genre, faisabilité, validation, diffusion).
A12: Conventions : High=3, Med=2, Low=1, UK=0 (Unknown). Coût/charge : Low=3, Med=2, High=1, UK=0.
A14: Attention : les formules évitent les fonctions de tableaux dynamiques (compatibilité).
A16: Ce que contient le classeur (et à quoi ça sert)
A18: Paramètres : barème High/Med/Low/UK (= 3/2/1/0) + inversion coût/charge + pondérations (modifiable).
... A33: Voici un classeur Excel complet (données simulées + formules) qui reproduit les principaux tableaux d’exploitation qu’on peut générer à partir du questionnaire (rubriques 1 à 13) et de la logique décrite dans le rapport méthodologique.

Sheet Paramètres
A1: Paramètres de codage et de calcul
A3: Codage standard (High/Med/Low/UK) | D3: Codage coût/charge (inversé) | G3: Pondérations des critères (modifiable)
A4: Libellé | B4: Score | D4: Libellé | E4: Score | G4: Demande | H4: Harmonisation | I4: Disponibilité | J4: Faisabilité | K4: Coût/charge | L4: Résultats rapides | M4: Impact genre
A5: High | B5: 3 | D5: Low | E5: 3 | F5: Poids | G5: 0.33333333 | H5: 0 | I5: 0.33333333 | J5: 0.33333333 | K5: 0 | L5: 0 | M5: 0
A6: Med | B6: 2 | D6: Med | E6: 2 | G6: Note : somme des poids = 1 (recommandé)
A7: Low | B7: 1 | D7: High | E7: 1
A8: UK | B8: 0 | D8: UK | E8: 0
A10: Points de rang (Top 5 domaines)
A11: Rang | B11: Points
A12: 1 | B12: 5
A13: 2 | B13: 4
A14: 3 | B14: 3
A15: 4 | B15: 2
A16: 5 | B16: 1

Sheet Référentiel_Domaines
A1: Code domaine | B1: Domaine
A2: D01 | B2: Croissance économique, transformation structurelle et commerce
A3: D02 | B3: Emploi, travail décent et protection sociale
A4: D03 | B4: Agriculture durable, sécurité alimentaire et nutrition
A5: D04 | B5: Infrastructures, industrialisation et innovation
A6: D05 | B6: Inclusion, pauvreté et inégalités
A7: D06 | B7: Éducation, compétences et capital humain
A8: D07 | B8: Santé, bien-être et accès universel
A9: D08 | B9: Égalité des genres et autonomisation
A10: D09 | B10: Environnement, résilience climatique et villes durables
A11: D10 | B11: Gouvernance, paix et institutions
A12: D11 | B12: Économie bleue et gestion des océans
A13: D12 | B13: Partenariats et financement du développement

Sheet Longlist_condensée
A1: ID indicateur | B1: Code domaine | C1: Indicateur (condensé) | D1: Source
A2: D01S01 | B2: D01 | C2: Taux de croissance du PIB réel | D2: UA(STYIP = 2e plan décennal de mise en œuvre)
A3: D01S02 | B3: D01 | C3: PIB par habitant (USD constant) | D3: UA (STYIP)
A4: D01S03 | B4: D01 | C4: Part de la Valeur Ajoutée Manufacturière (VAM) dans le PIB | D4: ODD 9.2 ; UA
A5: D01S04 | B5: D01 | C5: Part des produits de haute technologie dans les exportations manufacturées | D5: UA (STYIP)
A6: D01S05 | B6: D01 | C6: Part de l'Afrique dans la valeur ajoutée manufacturière mondiale | D6: UA (STYIP) ; ODD
A7: D01S06 | B7: D01 | C7: Part du commerce intra-africain dans le commerce total | D7: UA ; BAD
A8: D01S07 | B8: D01 | C8: Indice de diversification économique | D8: UA (STYIP)
A9: D01S08 | B9: D01 | C9: Contribution directe du tourisme au PIB | D9: UA (STYIP)
A10: D01S09 | B10: D01 | C10: Formation brute de capital fixe (% PIB) | D10: BAD
A11: D01S10 | B11: D01 | C11: Pays commerçant sous le régime ZLECA | D11: UA
A12: D02S11 | B12: D02 | C12: Taux de chômage (total, jeunes, femmes) | D12: UA (STYIP)
... A83: D12S80 | B83: D12 | C83: Indicateur D12S80 (à préciser) | D83: À préciser

Sheet Réponses_Répondants
A1: ID répondant | B1: Pays | C1: Région | D1: Type d’acteur | E1: Langue | F1: Portée réponse | G1: Consulté collègues | H1: SNDS active | I1: Pays (1ère occurrence) | J1: Flag pays unique
A2: R001 | B2: NER | C2: Ouest | D2: INS/NSO | E2: Français | F2: Global | G2: UK | H2: UK | I2: =IF(COUNTIF($B$2:B2,B2)=1,B2,"") -> NER | J2: =IF(I2<>"",1,0) -> 1
A3: R002 | B3: GHA | C3: Ouest | D3: Ministère/Ministry | E3: Français | F3: Régional | G3: UK | H3: UK | I3: =IF(COUNTIF($B$2:B3,B3)=1,B3,"") -> GHA | J3: =IF(I3<>"",1,0) -> 1
A4: R003 | B4: CIV | C4: Ouest | D4: OSC/CSO | E4: Français | F4: Continental | G4: UK | H4: UK | I4: =IF(COUNTIF($B$2:B4,B4)=1,B4,"") -> CIV | J4: =IF(I4<>"",1,0) -> 1
A5: R004 | B5: MLI | C5: Ouest | D5: INS/NSO | E5: Français | F5: National | G5: UK | H5: UK | I5: =IF(COUNTIF($B$2:B5,B5)=1,B5,"") -> MLI | J5: =IF(I5<>"",1,0) -> 1
A6: R005 | B6: SLE | C6: Ouest | D6: Ministère/Ministry | E6: Français | F6: National | G6: UK | H6: UK | I6: =IF(COUNTIF($B$2:B6,B6)=1,B6,"") -> SLE | J6: =IF(I6<>"",1,0) -> 1
A7: R006 | B7: EGY | C7: Nord | D7: INS/NSO | E7: Français | F7: National | G7: UK | H7: UK | I7: =IF(COUNTIF($B$2:B7,B7)=1,B7,"") -> EGY | J7: =IF(I7<>"",1,0) -> 1
A8: R007 | B8: ZAF | C8: Australe | D8: Académie/Academia | E8: Français | F8: Régional | G8: UK | H8: UK | I8: =IF(COUNTIF($B$2:B8,B8)=1,B8,"") -> ZAF | J8: =IF(I8<>"",1,0) -> 1
A9: R008 | B9: SEN | C9: Ouest | D9: INS/NSO | E9: Français | F9: National | G9: UK | H9: UK | I9: =IF(COUNTIF($B$2:B9,B9)=1,B9,"") -> SEN | J9: =IF(I9<>"",1,0) -> 1
A10: R009 | B10: ETH | C10: Est | D10: CER/REC | E10: Français | F10: Régional | G10: UK | H10: UK | I10: =IF(COUNTIF($B$2:B10,B10)=1,B10,"") -> ETH | J10: =IF(I10<>"",1,0) -> 1
A11: R010 | B11: TGO | C11: Ouest | D11: CER/REC | E11: Français | F11: National | G11: UK | H11: UK | I11: =IF(COUNTIF($B$2:B11,B11)=1,B11,"") -> TGO | J11: =IF(I11<>"",1,0) -> 1
A12: R011 | B12: EGY | C12: Nord | D12: CER/REC | E12: Français | F12: National | G12: UK | H12: UK | I12: =IF(COUNTIF($B$2:B12,B12)=1,B12,"") | J12: =IF(I12<>"",1,0) -> 0
A13: R012 | B13: ZAF | C13: Australe | D13: INS/NSO | E13: Français | F13: Régional | G13: UK | H13: UK | I13: =IF(COUNTIF($B$2:B13,B13)=1,B13,"") | J13: =IF(I13<>"",1,0) -> 0
... A201: R200 | B201: GHA | C201: Ouest | D201: Ministère/Ministry | E201: English | F201: Régional | G201: UK | H201: UK | I201: =IF(COUNTIF($B$2:B201,B201)=1,B201,"") | J201: =IF(I201<>"",1,0) -> 0

Sheet Aide_Pays
A1: Pays unique | B1: Nb pays uniques
A2: =Réponses_Répondants!I2 -> NER | B2: =COUNTA(Réponses_Répondants!$I$2:$I$5000) -> 200
A3: Note : La colonne I de Réponses_Répondants marque la première occurrence de chaque pays.

Sheet Réponses_Domaines
A1: ID répondant | B1: Code domaine | C1: Sélectionné (1/0) | D1: Rang Top5 (1-5) | E1: Points rang
A2: R001 | B2: D01 | C2: 1 | E2: =IF(D2="","",VLOOKUP(D2,Paramètres!$A$12:$B$16,2,FALSE))
A3: R001 | B3: D02 | C3: 1 | E3: =IF(D3="","",VLOOKUP(D3,Paramètres!$A$12:$B$16,2,FALSE))
A4: R001 | B4: D03 | C4: 1 | D4: 5 | E4: =IF(D4="","",VLOOKUP(D4,Paramètres!$A$12:$B$16,2,FALSE)) -> 1
A5: R001 | B5: D04 | C5: 1 | D5: 3 | E5: =IF(D5="","",VLOOKUP(D5,Paramètres!$A$12:$B$16,2,FALSE)) -> 3
A6: R001 | B6: D05 | C6: 1 | D6: 1 | E6: =IF(D6="","",VLOOKUP(D6,Paramètres!$A$12:$B$16,2,FALSE)) -> 5
A7: R001 | B7: D06 | C7: 1 | E7: =IF(D7="","",VLOOKUP(D7,Paramètres!$A$12:$B$16,2,FALSE))
A8: R001 | B8: D07 | C8: 0 | E8: =IF(D8="","",VLOOKUP(D8,Paramètres!$A$12:$B$16,2,FALSE))
A9: R001 | B9: D08 | C9: 1 | E9: =IF(D9="","",VLOOKUP(D9,Paramètres!$A$12:$B$16,2,FALSE))
A10: R001 | B10: D09 | C10: 0 | E10: =IF(D10="","",VLOOKUP(D10,Paramètres!$A$12:$B$16,2,FALSE))
A11: R001 | B11: D10 | C11: 1 | D11: 4 | E11: =IF(D11="","",VLOOKUP(D11,Paramètres!$A$12:$B$16,2,FALSE)) -> 2
A12: R001 | B12: D11 | C12: 1 | D12: 2 | E12: =IF(D12="","",VLOOKUP(D12,Paramètres!$A$12:$B$16,2,FALSE)) -> 4
A13: R001 | B13: D12 | C13: 1 | E13: =IF(D13="","",VLOOKUP(D13,Paramètres!$A$12:$B$16,2,FALSE))
A14: R002 | B14: D01 | C14: 1 | E14: =IF(D14="","",VLOOKUP(D14,Paramètres!$A$12:$B$16,2,FALSE))
A15: R002 | B15: D02 | C15: 1 | D15: 2 | E15: =IF(D15="","",VLOOKUP(D15,Paramètres!$A$12:$B$16,2,FALSE)) -> 4
A16: R002 | B16: D03 | C16: 1 | D16: 3 | E16: =IF(D16="","",VLOOKUP(D16,Paramètres!$A$12:$B$16,2,FALSE)) -> 3
A17: R002 | B17: D04 | C17: 0 | E17: =IF(D17="","",VLOOKUP(D17,Paramètres!$A$12:$B$16,2,FALSE))
A18: R002 | B18: D05 | C18: 1 | E18: =IF(D18="","",VLOOKUP(D18,Paramètres!$A$12:$B$16,2,FALSE))
A19: R002 | B19: D06 | C19: 1 | E19: =IF(D19="","",VLOOKUP(D19,Paramètres!$A$12:$B$16,2,FALSE))
A20: R002 | B20: D07 | C20: 0 | E20: =IF(D20="","",VLOOKUP(D20,Paramètres!$A$12:$B$16,2,FALSE))
A21: R002 | B21: D08 | C21: 1 | E21: =IF(D21="","",VLOOKUP(D21,Paramètres!$A$12:$B$16,2,FALSE))
A22: R002 | B22: D09 | C22: 1 | E22: =IF(D22="","",VLOOKUP(D22,Paramètres!$A$12:$B$16,2,FALSE))
A23: R002 | B23: D10 | C23: 1 | D23: 4 | E23: =IF(D23="","",VLOOKUP(D23,Paramètres!$A$12:$B$16,2,FALSE)) -> 2
A24: R002 | B24: D11 | C24: 1 | D24: 1 | E24: =IF(D24="","",VLOOKUP(D24,Paramètres!$A$12:$B$16,2,FALSE)) -> 5
A25: R002 | B25: D12 | C25: 1 | D25: 5 | E25: =IF(D25="","",VLOOKUP(D25,Paramètres!$A$12:$B$16,2,FALSE)) -> 1
A26: R003 | B26: D01 | C26: 1 | E26: =IF(D26="","",VLOOKUP(D26,Paramètres!$A$12:$B$16,2,FALSE))
A27: R003 | B27: D02 | C27: 0 | E27: =IF(D27="","",VLOOKUP(D27,Paramètres!$A$12:$B$16,2,FALSE))
A28: R003 | B28: D03 | C28: 0 | E28: =IF(D28="","",VLOOKUP(D28,Paramètres!$A$12:$B$16,2,FALSE))
A29: R003 | B29: D04 | C29: 1 | E29: =IF(D29="","",VLOOKUP(D29,Paramètres!$A$12:$B$16,2,FALSE))
A30: R003 | B30: D05 | C30: 1 | D30: 3 | E30: =IF(D30="","",VLOOKUP(D30,Paramètres!$A$12:$B$16,2,FALSE)) -> 3
A31: R003 | B31: D06 | C31: 1 | E31: =IF(D31="","",VLOOKUP(D31,Paramètres!$A$12:$B$16,2,FALSE))
A32: R003 | B32: D07 | C32: 1 | D32: 4 | E32: =IF(D32="","",VLOOKUP(D32,Paramètres!$A$12:$B$16,2,FALSE)) -> 2
A33: R003 | B33: D08 | C33: 1 | D33: 2 | E33: =IF(D33="","",VLOOKUP(D33,Paramètres!$A$12:$B$16,2,FALSE)) -> 4
A34: R003 | B34: D09 | C34: 1 | E34: =IF(D34="","",VLOOKUP(D34,Paramètres!$A$12:$B$16,2,FALSE))
A35: R003 | B35: D10 | C35: 1 | E35: =IF(D35="","",VLOOKUP(D35,Paramètres!$A$12:$B$16,2,FALSE))
A36: R003 | B36: D11 | C36: 1 | D36: 1 | E36: =IF(D36="","",VLOOKUP(D36,Paramètres!$A$12:$B$16,2,FALSE)) -> 5
A37: R003 | B37: D12 | C37: 1 | D37: 5 | E37: =IF(D37="","",VLOOKUP(D37,Paramètres!$A$12:$B$16,2,FALSE)) -> 1
A38: R004 | B38: D01 | C38: 1 | D38: 2 | E38: =IF(D38="","",VLOOKUP(D38,Paramètres!$A$12:$B$16,2,FALSE)) -> 4
A39: R004 | B39: D02 | C39: 0 | E39: =IF(D39="","",VLOOKUP(D39,Paramètres!$A$12:$B$16,2,FALSE))
A40: R004 | B40: D03 | C40: 0 | E40: =IF(D40="","",VLOOKUP(D40,Paramètres!$A$12:$B$16,2,FALSE))
...

Sheet Aide_Domaines_Pays
A1: Code domaine | B1: Pays | C1: Rang Top5 | D1: Clé (pays|domaine) | E1: 1ère occurrence (0/1)
A2: =Réponses_Domaines!B2 -> D01 | B2: =IFERROR(VLOOKUP(Réponses_Domaines!A2,Réponses_Répondants!$A$2:$B$5000,2,FALSE),"") -> NER | C2: =Réponses_Domaines!D2 -> 0 | D2: =B2&"|"&A2 -> NER|D01 | E2: =IF(C2="","",IF(COUNTIF($D$2:D2,D2)=1,1,0)) -> 1
A3: =Réponses_Domaines!B3 -> D02 | B3: =IFERROR(VLOOKUP(Réponses_Domaines!A3,Réponses_Répondants!$A$2:$B$5000,2,FALSE),"") -> NER | C3: =Réponses_Domaines!D3 -> 0 | D3: =B3&"|"&A3 -> NER|D02 | E3: =IF(C3="","",IF(COUNTIF($D$2:D3,D3)=1,1,0)) -> 1
A4: =Réponses_Domaines!B4 -> D03 | B4: =IFERROR(VLOOKUP(Réponses_Domaines!A4,Réponses_Répondants!$A$2:$B$5000,2,FALSE),"") -> NER | C4: =Réponses_Domaines!D4 -> 5 | D4: =B4&"|"&A4 -> NER|D03 | E4: =IF(C4="","",IF(COUNTIF($D$2:D4,D4)=1,1,0)) -> 1
A5: =Réponses_Domaines!B5 -> D04 | B5: =IFERROR(VLOOKUP(Réponses_Domaines!A5,Réponses_Répondants!$A$2:$B$5000,2,FALSE),"") -> NER | C5: =Réponses_Domaines!D5 -> 3 | D5: =B5&"|"&A5 -> NER|D04 | E5: =IF(C5="","",IF(COUNTIF($D$2:D5,D5)=1,1,0)) -> 1
A6: =Réponses_Domaines!B6 -> D05 | B6: =IFERROR(VLOOKUP(Réponses_Domaines!A6,Réponses_Répondants!$A$2:$B$5000,2,FALSE),"") -> NER | C6: =Réponses_Domaines!D6 -> 1 | D6: =B6&"|"&A6 -> NER|D05 | E6: =IF(C6="","",IF(COUNTIF($D$2:D6,D6)=1,1,0)) -> 1
A7: =Réponses_Domaines!B7 -> D06 | B7: =IFERROR(VLOOKUP(Réponses_Domaines!A7,Réponses_Répondants!$A$2:$B$5000,2,FALSE),"") -> NER | C7: =Réponses_Domaines!D7 -> 0 | D7: =B7&"|"&A7 -> NER|D06 | E7: =IF(C7="","",IF(COUNTIF($D$2:D7,D7)=1,1,0)) -> 1
A8: =Réponses_Domaines!B8 -> D07 | B8: =IFERROR(VLOOKUP(Réponses_Domaines!A8,Réponses_Répondants!$A$2:$B$5000,2,FALSE),"") -> NER | C8: =Réponses_Domaines!D8 -> 0 | D8: =B8&"|"&A8 -> NER|D07 | E8: =IF(C8="","",IF(COUNTIF($D$2:D8,D8)=1,1,0)) -> 1
A9: =Réponses_Domaines!B9 -> D08 | B9: =IFERROR(VLOOKUP(Réponses_Domaines!A9,Réponses_Répondants!$A$2:$B$5000,2,FALSE),"") -> NER | C9: =Réponses_Domaines!D9 -> 0 | D9: =B9&"|"&A9 -> NER|D08 | E9: =IF(C9="","",IF(COUNTIF($D$2:D9,D9)=1,1,0)) -> 1
A10: =Réponses_Domaines!B10 -> D09 | B10: =IFERROR(VLOOKUP(Réponses_Domaines!A10,Réponses_Répondants!$A$2:$B$5000,2,FALSE),"") -> NER | C10: =Réponses_Domaines!D10 -> 0 | D10: =B10&"|"&A10 -> NER|D09 | E10: =IF(C10="","",IF(COUNTIF($D$2:D10,D10)=1,1,0)) -> 1
A11: =Réponses_Domaines!B11 -> D10 | B11: =IFERROR(VLOOKUP(Réponses_Domaines!A11,Réponses_Répondants!$A$2:$B$5000,2,FALSE),"") -> NER | C11: =Réponses_Domaines!D11 -> 4 | D11: =B11&"|"&A11 -> NER|D10 | E11: =IF(C11="","",IF(COUNTIF($D$2:D11,D11)=1,1,0)) -> 1
A12: =Réponses_Domaines!B12 -> D11 | B12: =IFERROR(VLOOKUP(Réponses_Domaines!A12,Réponses_Répondants!$A$2:$B$5000,2,FALSE),"") -> NER | C12: =Réponses_Domaines!D12 -> 2 | D12: =B12&"|"&A12 -> NER|D11 | E12: =IF(C12="","",IF(COUNTIF($D$2:D12,D12)=1,1,0)) -> 1
A13: =Réponses_Domaines!B13 -> D12 | B13: =IFERROR(VLOOKUP(Réponses_Domaines!A13,Réponses_Répondants!$A$2:$B$5000,2,FALSE),"") -> NER | C13: =Réponses_Domaines!D13 -> 0 | D13: =B13&"|"&A13 -> NER|D12 | E13: =IF(C13="","",IF(COUNTIF($D$2:D13,D13)=1,1,0)) -> 1
... A3001: =Réponses_Domaines!B3001 -> 0 | B3001: =IFERROR(VLOOKUP(Réponses_Domaines!A3001,Réponses_Répondants!$A$2:$B$5000,2,FALSE),"") | C3001: =Réponses_Domaines!D3001 -> 0 | D3001: =B3001&"|"&A3001 -> |0 | E3001: =IF(C3001="","",IF(COUNTIF($D$2:D3001,D3001)=1,1,0)) -> 0

Sheet Réponses_Indicateurs
A1: ID répondant | B1: Pays | C1: Code domaine | D1: ID indicateur | E1: Indicateur | F1: Source | G1: Alignement UA | H1: Alignement ODD | I1: Alignement BAD | J1: Sexe (Yes/No/UK) | K1: Périodicité | L1: Niveau | M1: Note
A2: R001 | B2: NER | C2: D05 | D2: D05S41 | E2: Accès à l'eau (Pays en transition/fragiles) | F2: BAD | G2: Asp1 | H2: SDG 4 | I2: P5 | J2: No | K2: Qtr | L2: Cont
A3: R001 | B3: NER | C3: D11 | D3: D11S73 | E3: Pénétration de l'énergie bleue | F3: UA (STYIP) | G3: Asp4 | H3: SDG 1 | I3: P5 | J3: UK | K3: Other | L3: Cont
A4: R001 | B4: NER | C4: D11 | D4: D11S74 | E4: Stocks de poissons durables | F4: ODD 14.4 | G4: Asp6 | H4: SDG 4 | I4: P3 | J4: UK | K4: Qtr | L4: Cont
A5: R001 | B5: NER | C5: D11 | D5: D11S75 | E5: Indicateur D11S75 (à préciser) | F5: À préciser | G5: Asp4 | H5: SDG 1 | I5: P3 | J5: No | K5: Annual | L5: REC
A6: R001 | B6: NER | C6: D04 | D6: D04S29 | E6: Connectivité routière interafricaine | F6: UA (STYIP) | G6: Asp7 | H6: SDG 6 | I6: P1 | J6: No | K6: Other | L6: Cont
A7: R001 | B7: NER | C7: D04 | D7: D04S33 | E7: Contribution des services numériques au PIB | F7: UA (STYIP) | G7: Asp1 | H7: SDG 2 | I7: P2 | J7: No | K7: Other | L7: Nat
A8: R001 | B8: NER | C8: D10 | D8: D10S68 | E8: Perception d'indépendance de la justice | F8: UA (STYIP) | G8: Asp7 | H8: SDG 14 | I8: P2 | J8: Yes | K8: Other | L8: Cont
A9: R001 | B9: NER | C9: D10 | D9: D10S67 | E9: Flux Financiers Illicites (% PIB) | F9: UA (STYIP) ; ODD 16.4 | G9: Asp5 | H9: SDG 11 | I9: P4 | J9: UK | K9: Other | L9: Cont
A10: R001 | B10: NER | C10: D10 | D10: D10S69 | E10: Ratio recettes fiscales / PIB | F10: UA (STYIP) | G10: Asp7 | H10: SDG 9 | I10: P5 | J10: No | K10: Other | L10: Nat
A11: R001 | B11: NER | C11: D03 | D11: D03S26 | E11: Utilisation d'engrais (kg/ha) | F11: UA (Abuja) | G11: Asp6 | H11: SDG 7 | I11: P1 | J11: No | K11: Qtr | L11: REC
A12: R001 | B12: NER | C12: D03 | D12: D03S24 | E12: Résilience climatique des ménages agricoles | F12: UA (STYIP) | G12: Asp7 | H12: SDG 13 | I12: P4 | J12: Yes | K12: Qtr | L12: REC
A13: R001 | B13: NER | C13: D03 | D13: D03S23 | E13: Terres sous gestion durable | F13: UA (Post-Malabo) | G13: Asp2 | H13: SDG 16 | I13: P2 | J13: No | K13: Qtr | L13: REC
... A271: R028 | B271: ZAF | C271: D12 | D271: D12S80 | E271: Indicateur D12S80 (à préciser) | F271: À préciser | G271: Asp7 | H271: SDG 1 | I271: P5 | J271: Yes | K271: Annual | L271: REC
A272: R028 | B272: ZAF | C272: D12 | D272: D12S77 | E272: Part du budget financé par impôts nationaux | F272: ODD 17.1 ; UA
A273: R028 | B273: ZAF | C273: D12 | D273: D12S76 | E273: Flux financiers illicites (% PIB) | F273: UA (STYIP)
A274: R028 | B274: ZAF | C274: D04 | D274: D04S33 | E274: Contribution des services numériques au PIB | F274: UA (STYIP)
A275: R028 | B275: ZAF | C275: D04 | D275: D04S28 | E275: Accès Internet haut débit (Qualité) | F275: UA (STYIP)
A276: R028 | B276: ZAF | C276: D04 | D276: D04S27 | E276: Taux d’accès à l'électricité (Ménages) | F276: UA (STYIP) ; ODD 7.1
A277: R029 | B277: TGO | C277: D06 | D277: D06S42 | E277: Taux net de scolarisation (Primaire) | F277: UA (STYIP) ; ODD 4.1
A278: R029 | B278: TGO | C278: D06 | D278: D06S46 | E278: Taux de compétence minimale (Lecture/Maths) | F278: UA (STYIP) ; ODD 4.1
A279: R029 | B279: TGO | C279: D02 | D279: D02S13 | E279: Taux de jeunes NEET (15-24 ans) | F279: ODD 8.6 ; UA
A280: R029 | B280: TGO | C280: D10 | D280: D10S68 | E280: Perception d'indépendance de la justice | F280: UA (STYIP)
A281: R029 | B281: TGO | C281: D09 | D281: D09S61 | E281: Pertes économiques dues aux catastrophes | F281: UA (STYIP)
A282: R029 | B282: TGO | C282: D09 | D282: D09S63 | E282: Ménages avec résilience climatique renforcée | F282: UA (STYIP)
A283: R029 | B283: TGO | C283: D09 | D283: D09S62 | E283: Couverture forestière | F283: UA (STYIP) ; ODD 15.1
... A1961: R200 | B1961: GHA | C1961: D01 | D1961: D01S04 | E1961: Part des produits de haute technologie dans les exportations manufacturées | F1961: UA (STYIP)

Sheet Aide_Indicateurs_Pays
A1: ID indicateur | B1: Pays | C1: Clé (indicateur|pays) | D1: 1ère occurrence (0/1)
A2: =Réponses_Indicateurs!D2 -> D05S41 | B2: =Réponses_Indicateurs!B2 -> NER | C2: =A2&"|"&B2 -> D05S41|NER | D2: =IF(COUNTIF($C$2:C2,C2)=1,1,0) -> 1
A3: =Réponses_Indicateurs!D3 -> D11S73 | B3: =Réponses_Indicateurs!B3 -> NER | C3: =A3&"|"&B3 -> D11S73|NER | D3: =IF(COUNTIF($C$2:C3,C3)=1,1,0) -> 1
A4: =Réponses_Indicateurs!D4 -> D11S74 | B4: =Réponses_Indicateurs!B4 -> NER | C4: =A4&"|"&B4 -> D11S74|NER | D4: =IF(COUNTIF($C$2:C4,C4)=1,1,0) -> 1
A5: =Réponses_Indicateurs!D5 -> D11S75 | B5: =Réponses_Indicateurs!B5 -> NER | C5: =A5&"|"&B5 -> D11S75|NER | D5: =IF(COUNTIF($C$2:C5,C5)=1,1,0) -> 1
A6: =Réponses_Indicateurs!D6 -> D04S29 | B6: =Réponses_Indicateurs!B6 -> NER | C6: =A6&"|"&B6 -> D04S29|NER | D6: =IF(COUNTIF($C$2:C6,C6)=1,1,0) -> 1
A7: =Réponses_Indicateurs!D7 -> D04S33 | B7: =Réponses_Indicateurs!B7 -> NER | C7: =A7&"|"&B7 -> D04S33|NER | D7: =IF(COUNTIF($C$2:C7,C7)=1,1,0) -> 1
A8: =Réponses_Indicateurs!D8 -> D10S68 | B8: =Réponses_Indicateurs!B8 -> NER | C8: =A8&"|"&B8 -> D10S68|NER | D8: =IF(COUNTIF($C$2:C8,C8)=1,1,0) -> 1
A9: =Réponses_Indicateurs!D9 -> D10S67 | B9: =Réponses_Indicateurs!B9 -> NER | C9: =A9&"|"&B9 -> D10S67|NER | D9: =IF(COUNTIF($C$2:C9,C9)=1,1,0) -> 1
A10: =Réponses_Indicateurs!D10 -> D10S69 | B10: =Réponses_Indicateurs!B10 -> NER | C10: =A10&"|"&B10 -> D10S69|NER | D10: =IF(COUNTIF($C$2:C10,C10)=1,1,0) -> 1
A11: =Réponses_Indicateurs!D11 -> D03S26 | B11: =Réponses_Indicateurs!B11 -> NER | C11: =A11&"|"&B11 -> D03S26|NER | D11: =IF(COUNTIF($C$2:C11,C11)=1,1,0) -> 1
A12: =Réponses_Indicateurs!D12 -> D03S24 | B12: =Réponses_Indicateurs!B12 -> NER | C12: =A12&"|"&B12 -> D03S24|NER | D12: =IF(COUNTIF($C$2:C12,C12)=1,1,0) -> 1
A13: =Réponses_Indicateurs!D13 -> D03S23 | B13: =Réponses_Indicateurs!B13 -> NER | C13: =A13&"|"&B13 -> D03S23|NER | D13: =IF(COUNTIF($C$2:C13,C13)=1,1,0) -> 1
... A3001: =Réponses_Indicateurs!D3001 -> 0 | B3001: =Réponses_Indicateurs!B3001 -> 0 | C3001: =A3001&"|"&B3001 -> 0|0 | D3001: =IF(COUNTIF($C$2:C3001,C3001)=1,1,0) -> 0

Sheet Réponses_Scoring
A1: ID répondant | B1: ID indicateur | C1: Demande | D1: Harmonisation | E1: Disponibilité | F1: Faisabilité | G1: Coût/charge | H1: Résultats rapides | I1: Impact genre | J1: Commentaire
A2: R001 | B2: D05S41 | C2: Med | D2: UK | E2: Med | F2: Low | G2: UK | H2: UK | I2: UK
A3: R001 | B3: D11S73 | C3: High | D3: UK | E3: High | F3: High | G3: UK | H3: UK | I3: UK
A4: R001 | B4: D11S74 | C4: High | D4: UK | E4: Low | F4: Med | G4: UK | H4: UK | I4: UK
A5: R001 | B5: D11S75 | C5: Low | D5: UK | E5: Low | F5: Med | G5: UK | H5: UK | I5: UK
A6: R001 | B6: D04S29 | C6: Low | D6: UK | E6: Med | F6: Low | G6: UK | H6: UK | I6: UK
A7: R001 | B7: D04S33 | C7: Med | D7: UK | E7: Med | F7: Med | G7: UK | H7: UK | I7: UK
A8: R001 | B8: D10S68 | C8: Med | D8: UK | E8: Med | F8: Low | G8: UK | H8: UK | I8: UK
A9: R001 | B9: D10S67 | C9: Med | D9: UK | E9: Med | F9: Low | G9: UK | H9: UK | I9: UK
A10: R001 | B10: D10S69 | C10: Med | D10: UK | E10: High | F10: UK | G10: UK | H10: UK | I10: UK
A11: R001 | B11: D03S26 | C11: High | D11: UK | E11: Low | F11: Med | G11: UK | H11: UK | I11: UK
A12: R001 | B12: D03S24 | C12: High | D12: UK | E12: Low | F12: UK | G12: UK | H12: UK | I12: UK
A13: R001 | B13: D03S23 | C13: High | D13: UK | E13: High | F13: High | G13: UK | H13: UK | I13: UK
... A1961: R200 | B1961: D01S04 | C1961: High | D1961: UK | E1961: Med | F1961: High | G1961: UK | H1961: UK | I1961: UK

Sheet Codage_Scoring
A1: ID répondant | B1: ID indicateur | C1: Demande_txt | D1: Harmonisation_txt | E1: Disponibilité_txt | F1: Faisabilité_txt | G1: Coût_txt | H1: Rapides_txt | I1: Genre_txt | J1: Demande_score | K1: Harmonisation_score | L1: Disponibilité_score | M1: Faisabilité_score | N1: Coût_score | O1: Rapides_score | P1: Genre_score | Q1: Score global (pondéré)
A2: =Réponses_Scoring!A2 -> R001 | B2: =Réponses_Scoring!B2 -> D05S41 | C2: =Réponses_Scoring!C2 -> Med | D2: =Réponses_Scoring!D2 -> UK | E2: =Réponses_Scoring!E2 -> Med | F2: =Réponses_Scoring!F2 -> Low | G2: =Réponses_Scoring!G2 -> UK | H2: =Réponses_Scoring!H2 -> UK | I2: =Réponses_Scoring!I2 -> UK | J2: =IFERROR(VLOOKUP(C2,Paramètres!$A$5:$B$8,2,FALSE),0) -> 2 | K2: =IFERROR(VLOOKUP(D2,Paramètres!$A$5:$B$8,2,FALSE),0) -> 0 | L2: =IFERROR(VLOOKUP(E2,Paramètres!$A$5:$B$8,2,FALSE),0) -> 2 | M2: =IFERROR(VLOOKUP(F2,Paramètres!$A$5:$B$8,2,FALSE),0) -> 1 | N2: =IFERROR(VLOOKUP(G2,Paramètres!$D$5:$E$8,2,FALSE),0) -> 0 | O2: =IFERROR(VLOOKUP(H2,Paramètres!$A$5:$B$8,2,FALSE),0) -> 0 | P2: =IFERROR(VLOOKUP(I2,Paramètres!$A$5:$B$8,2,FALSE),0) -> 0 | Q2: =IF(SUM(Paramètres!$G$5:$M$5)=0,"",SUMPRODUCT(Paramètres!$G$5:$M$5,J2,K2,L2,M2,N2,O2,P2)/SUM(Paramètres!$G$5:$M$5)) -> #VALUE!
A3: =Réponses_Scoring!A3 -> R001 | B3: =Réponses_Scoring!B3 -> D11S73 | C3: =Réponses_Scoring!C3 -> High | D3: =Réponses_Scoring!D3 -> UK | E3: =Réponses_Scoring!E3 -> High | F3: =Réponses_Scoring!F3 -> High | G3: =Réponses_Scoring!G3 -> UK | H3: =Réponses_Scoring!H3 -> UK | I3: =Réponses_Scoring!I3 -> UK | J3: =IFERROR(VLOOKUP(C3,Paramètres!$A$5:$B$8,2,FALSE),0) -> 3 | K3: =IFERROR(VLOOKUP(D3,Paramètres!$A$5:$B$8,2,FALSE),0) -> 0 | L3: =IFERROR(VLOOKUP(E3,Paramètres!$A$5:$B$8,2,FALSE),0) -> 3 | M3: =IFERROR(VLOOKUP(F3,Paramètres!$A$5:$B$8,2,FALSE),0) -> 3 | N3: =IFERROR(VLOOKUP(G3,Paramètres!$D$5:$E$8,2,FALSE),0) -> 0 | O3: =IFERROR(VLOOKUP(H3,Paramètres!$A$5:$B$8,2,FALSE),0) -> 0 | P3: =IFERROR(VLOOKUP(I3,Paramètres!$A$5:$B$8,2,FALSE),0) -> 0 | Q3: =IF(SUM(Paramètres!$G$5:$M$5)=0,"",SUMPRODUCT(Paramètres!$G$5:$M$5,J3,K3,L3,M3,N3,O3,P3)/SUM(Paramètres!$G$5:$M$5)) -> #VALUE!
A4: =Réponses_Scoring!A4 -> R001 | B4: =Réponses_Scoring!B4 -> D11S74 | C4: =Réponses_Scoring!C4 -> High | D4: =Réponses_Scoring!D4 -> UK | E4: =Réponses_Scoring!E4 -> Low | F4: =Réponses_Scoring!F4 -> Med | G4: =Réponses_Scoring!G4 -> UK | H4: =Réponses_Scoring!H4 -> UK | I4: =Réponses_Scoring!I4 -> UK | J4: =IFERROR(VLOOKUP(C4,Paramètres!$A$5:$B$8,2,FALSE),0) -> 3 | K4: =IFERROR(VLOOKUP(D4,Paramètres!$A$5:$B$8,2,FALSE),0) -> 0 | L4: =IFERROR(VLOOKUP(E4,Paramètres!$A$5:$B$8,2,FALSE),0) -> 1 | M4: =IFERROR(VLOOKUP(F4,Paramètres!$A$5:$B$8,2,FALSE),0) -> 2 | N4: =IFERROR(VLOOKUP(G4,Paramètres!$D$5:$E$8,2,FALSE),0) -> 0 | O4: =IFERROR(VLOOKUP(H4,Paramètres!$A$5:$B$8,2,FALSE),0) -> 0 | P4: =IFERROR(VLOOKUP(I4,Paramètres!$A$5:$B$8,2,FALSE),0) -> 0 | Q4: =IF(SUM(Paramètres!$G$5:$M$5)=0,"",SUMPRODUCT(Paramètres!$G$5:$M$5,J4,K4,L4,M4,N4,O4,P4)/SUM(Paramètres!$G$5:$M$5)) -> #VALUE!
A5: =Réponses_Scoring!A5 -> R001 | B5: =Réponses_Scoring!B5 -> D11S75 | C5: =Réponses_Scoring!C5 -> Low | D5: =Réponses_Scoring!D5 -> UK | E5: =Réponses_Scoring!E5 -> Low | F5: =Réponses_Scoring!F5 -> Med | G5: =Réponses_Scoring!G5 -> UK | H5: =Réponses_Scoring!H5 -> UK | I5: =Réponses_Scoring!I5 -> UK | J5: =IFERROR(VLOOKUP(C5,Paramètres!$A$5:$B$8,2,FALSE),0) -> 1 | K5: =IFERROR(VLOOKUP(D5,Paramètres!$A$5:$B$8,2,FALSE),0) -> 0 | L5: =IFERROR(VLOOKUP(E5,Paramètres!$A$5:$B$8,2,FALSE),0) -> 1 | M5: =IFERROR(VLOOKUP(F5,Paramètres!$A$5:$B$8,2,FALSE),0) -> 2 | N5: =IFERROR(VLOOKUP(G5,Paramètres!$D$5:$E$8,2,FALSE),0) -> 0 | O5: =IFERROR(VLOOKUP(H5,Paramètres!$A$5:$B$8,2,FALSE),0) -> 0 | P5: =IFERROR(VLOOKUP(I5,Paramètres!$A$5:$B$8,2,FALSE),0) -> 0 | Q5: =IF(SUM(Paramètres!$G$5:$M$5)=0,"",SUMPRODUCT(Paramètres!$G$5:$M$5,J5,K5,L5,M5,N5,O5,P5)/SUM(Paramètres!$G$5:$M$5)) -> #VALUE!
A6: =Réponses_Scoring!A6 -> R001 | B6: =Réponses_Scoring!B6 -> D04S29 | C6: =Réponses_Scoring!C6 -> Low | D6: =Réponses_Scoring!D6 -> UK | E6: =Réponses_Scoring!E6 -> Med | F6: =Réponses_Scoring!F6 -> Low | G6: =Réponses_Scoring!G6 -> UK | H6: =Réponses_Scoring!H6 -> UK | I6: =Réponses_Scoring!I6 -> UK | J6: =IFERROR(VLOOKUP(C6,Paramètres!$A$5:$B$8,2,FALSE),0) -> 1 | K6: =IFERROR(VLOOKUP(D6,Paramètres!$A$5:$B$8,2,FALSE),0) -> 0 | L6: =IFERROR(VLOOKUP(E6,Paramètres!$A$5:$B$8,2,FALSE),0) -> 2 | M6: =IFERROR(VLOOKUP(F6,Paramètres!$A$5:$B$8,2,FALSE),0) -> 1 | N6: =IFERROR(VLOOKUP(G6,Paramètres!$D$5:$E$8,2,FALSE),0) -> 0 | O6: =IFERROR(VLOOKUP(H6,Paramètres!$A$5:$B$8,2,FALSE),0) -> 0 | P6: =IFERROR(VLOOKUP(I6,Paramètres!$A$5:$B$8,2,FALSE),0) -> 0 | Q6: =IF(SUM(Paramètres!$G$5:$M$5)=0,"",SUMPRODUCT(Paramètres!$G$5:$M$5,J6,K6,L6,M6,N6,O6,P6)/SUM(Paramètres!$G$5:$M$5)) -> #VALUE!
A7: =Réponses_Scoring!A7 -> R001 | B7: =Réponses_Scoring!B7 -> D04S33 | C7: =Réponses_Scoring!C7 -> Med | D7: =Réponses_Scoring!D7 -> UK | E7: =Réponses_Scoring!E7 -> Med | F7: =Réponses_Scoring!F7 -> Med | G7: =Réponses_Scoring!G7 -> UK | H7: =Réponses_Scoring!H7 -> UK | I7: =Réponses_Scoring!I7 -> UK | J7: =IFERROR(VLOOKUP(C7,Paramètres!$A$5:$B$8,2,FALSE),0) -> 2 | K7: =IFERROR(VLOOKUP(D7,Paramètres!$A$5:$B$8,2,FALSE),0) -> 0 | L7: =IFERROR(VLOOKUP(E7,Paramètres!$A$5:$B$8,2,FALSE),0) -> 2 | M7: =IFERROR(VLOOKUP(F7,Paramètres!$A$5:$B$8,2,FALSE),0) -> 2 | N7: =IFERROR(VLOOKUP(G7,Paramètres!$D$5:$E$8,2,FALSE),0) -> 0 | O7: =IFERROR(VLOOKUP(H7,Paramètres!$A$5:$B$8,2,FALSE),0) -> 0 | P7: =IFERROR(VLOOKUP(I7,Paramètres!$A$5:$B$8,2,FALSE),0) -> 0 | Q7: =IF(SUM(Paramètres!$G$5:$M$5)=0,"",SUMPRODUCT(Paramètres!$G$5:$M$5,J7,K7,L7,M7,N7,O7,P7)/SUM(Paramètres!$G$5:$M$5)) -> #VALUE!
A8: =Réponses_Scoring!A8 -> R001 | B8: =Réponses_Scoring!B8 -> D10S68 | C8: =Réponses_Scoring!C8 -> Med | D8: =Réponses_Scoring!D8 -> UK | E8: =Réponses_Scoring!E8 -> Med | F8: =Réponses_Scoring!F8 -> Low | G8: =Réponses_Scoring!G8 -> UK | H8: =Réponses_Scoring!H8 -> UK | I8: =Réponses_Scoring!I8 -> UK | J8: =IFERROR(VLOOKUP(C8,Paramètres!$A$5:$B$8,2,FALSE),0) -> 2 | K8: =IFERROR(VLOOKUP(D8,Paramètres!$A$5:$B$8,2,FALSE),0) -> 0 | L8: =IFERROR(VLOOKUP(E8,Paramètres!$A$5:$B$8,2,FALSE),0) -> 2 | M8: =IFERROR(VLOOKUP(F8,Paramètres!$A$5:$B$8,2,FALSE),0) -> 1 | N8: =IFERROR(VLOOKUP(G8,Paramètres!$D$5:$E$8,2,FALSE),0) -> 0 | O8: =IFERROR(VLOOKUP(H8,Paramètres!$A$5:$B$8,2,FALSE),0) -> 0 | P8: =IFERROR(VLOOKUP(I8,Paramètres!$A$5:$B$8,2,FALSE),0) -> 0 | Q8: =IF(SUM(Paramètres!$G$5:$M$5)=0,"",SUMPRODUCT(Paramètres!$G$5:$M$5,J8,K8,L8,M8,N8,O8,P8)/SUM(Paramètres!$G$5:$M$5)) -> #VALUE!
A9: =Réponses_Scoring!A9 -> R001 | B9: =Réponses_Scoring!B9 -> D10S67 | C9: =Réponses_Scoring!C9 -> Med | D9: =Réponses_Scoring!D9 -> UK | E9: =Réponses_Scoring!E9 -> Med | F9: =Réponses_Scoring!F9 -> Low | G9: =Réponses_Scoring!G9 -> UK | H9: =Réponses_Scoring!H9 -> UK | I9: =Réponses_Scoring!I9 -> UK | J9: =IFERROR(VLOOKUP(C9,Paramètres!$A$5:$B$8,2,FALSE),0) -> 2 | K9: =IFERROR(VLOOKUP(D9,Paramètres!$A$5:$B$8,2,FALSE),0) -> 0 | L9: =IFERROR(VLOOKUP(E9,Paramètres!$A$5:$B$8,2,FALSE),0) -> 2 | M9: =IFERROR(VLOOKUP(F9,Paramètres!$A$5:$B$8,2,FALSE),0) -> 1 | N9: =IFERROR(VLOOKUP(G9,Paramètres!$D$5:$E$8,2,FALSE),0) -> 0 | O9: =IFERROR(VLOOKUP(H9,Paramètres!$A$5:$B$8,2,FALSE),0) -> 0 | P9: =IFERROR(VLOOKUP(I9,Paramètres!$A$5:$B$8,2,FALSE),0) -> 0 | Q9: =IF(SUM(Paramètres!$G$5:$M$5)=0,"",SUMPRODUCT(Paramètres!$G$5:$M$5,J9,K9,L9,M9,N9,O9,P9)/SUM(Paramètres!$G$5:$M$5)) -> #VALUE!
A10: =Réponses_Scoring!A10 -> R001 | B10: =Réponses_Scoring!B10 -> D10S69 | C10: =Réponses_Scoring!C10 -> Med | D10: =Réponses_Scoring!D10 -> UK | E10: =Réponses_Scoring!E10 -> High | F10: =Réponses_Scoring!F10 -> UK | G10: =Réponses_Scoring!G10 -> UK | H10: =Réponses_Scoring!H10 -> UK | I10: =Réponses_Scoring!I10 -> UK | J10: =IFERROR(VLOOKUP(C10,Paramètres!$A$5:$B$8,2,FALSE),0) -> 2 | K10: =IFERROR(VLOOKUP(D10,Paramètres!$A$5:$B$8,2,FALSE),0) -> 0 | L10: =IFERROR(VLOOKUP(E10,Paramètres!$A$5:$B$8,2,FALSE),0) -> 3 | M10: =IFERROR(VLOOKUP(F10,Paramètres!$A$5:$B$8,2,FALSE),0) -> 0 | N10: =IFERROR(VLOOKUP(G10,Paramètres!$D$5:$E$8,2,FALSE),0) -> 0 | O10: =IFERROR(VLOOKUP(H10,Paramètres!$A$5:$B$8,2,FALSE),0) -> 0 | P10: =IFERROR(VLOOKUP(I10,Paramètres!$A$5:$B$8,2,FALSE),0) -> 0 | Q10: =IF(SUM(Paramètres!$G$5:$M$5)=0,"",SUMPRODUCT(Paramètres!$G$5:$M$5,J10,K10,L10,M10,N10,O10,P10)/SUM(Paramètres!$G$5:$M$5)) -> #VALUE!
A11: =Réponses_Scoring!A11 -> R001 | B11: =Réponses_Scoring!B11 -> D03S26 | C11: =Réponses_Scoring!C11 -> High | D11: =Réponses_Scoring!D11 -> UK | E11: =Réponses_Scoring!E11 -> Low | F11: =Réponses_Scoring!F11 -> Med | G11: =Réponses_Scoring!G11 -> UK | H11: =Réponses_Scoring!H11 -> UK | I11: =Réponses_Scoring!I11 -> UK | J11: =IFERROR(VLOOKUP(C11,Paramètres!$A$5:$B$8,2,FALSE),0) -> 3 | K11: =IFERROR(VLOOKUP(D11,Paramètres!$A$5:$B$8,2,FALSE),0) -> 0 | L11: =IFERROR(VLOOKUP(E11,Paramètres!$A$5:$B$8,2,FALSE),0) -> 1 | M11: =IFERROR(VLOOKUP(F11,Paramètres!$A$5:$B$8,2,FALSE),0) -> 2 | N11: =IFERROR(VLOOKUP(G11,Paramètres!$D$5:$E$8,2,FALSE),0) -> 0 | O11: =IFERROR(VLOOKUP(H11,Paramètres!$A$5:$B$8,2,FALSE),0) -> 0 | P11: =IFERROR(VLOOKUP(I11,Paramètres!$A$5:$B$8,2,FALSE),0) -> 0 | Q11: =IF(SUM(Paramètres!$G$5:$M$5)=0,"",SUMPRODUCT(Paramètres!$G$5:$M$5,J11,K11,L11,M11,N11,O11,P11)/SUM(Paramètres!$G$5:$M$5)) -> #VALUE!
A12: =Réponses_Scoring!A12 -> R001 | B12: =Réponses_Scoring!B12 -> D03S24 | C12: =Réponses_Scoring!C12 -> High | D12: =Réponses_Scoring!D12 -> UK | E12: =Réponses_Scoring!E12 -> Low | F12: =Réponses_Scoring!F12 -> UK | G12: =Réponses_Scoring!G12 -> UK | H12: =Réponses_Scoring!H12 -> UK | I12: =Réponses_Scoring!I12 -> UK | J12: =IFERROR(VLOOKUP(C12,Paramètres!$A$5:$B$8,2,FALSE),0) -> 3 | K12: =IFERROR(VLOOKUP(D12,Paramètres!$A$5:$B$8,2,FALSE),0) -> 0 | L12: =IFERROR(VLOOKUP(E12,Paramètres!$A$5:$B$8,2,FALSE),0) -> 1 | M12: =IFERROR(VLOOKUP(F12,Paramètres!$A$5:$B$8,2,FALSE),0) -> 0 | N12: =IFERROR(VLOOKUP(G12,Paramètres!$D$5:$E$8,2,FALSE),0) -> 0 | O12: =IFERROR(VLOOKUP(H12,Paramètres!$A$5:$B$8,2,FALSE),0) -> 0 | P12: =IFERROR(VLOOKUP(I12,Paramètres!$A$5:$B$8,2,FALSE),0) -> 0 | Q12: =IF(SUM(Paramètres!$G$5:$M$5)=0,"",SUMPRODUCT(Paramètres!$G$5:$M$5,J12,K12,L12,M12,N12,O12,P12)/SUM(Paramètres!$G$5:$M$5)) -> #VALUE!
A13: =Réponses_Scoring!A13 -> R001 | B13: =Réponses_Scoring!B13 -> D03S23 | C13: =Réponses_Scoring!C13 -> High | D13: =Réponses_Scoring!D13 -> UK | E13: =Réponses_Scoring!E13 -> High | F13: =Réponses_Scoring!F13 -> High | G13: =Réponses_Scoring!G13 -> UK | H13: =Réponses_Scoring!H13 -> UK | I13: =Réponses_Scoring!I13 -> UK | J13: =IFERROR(VLOOKUP(C13,Paramètres!$A$5:$B$8,2,FALSE),0) -> 3 | K13: =IFERROR(VLOOKUP(D13,Paramètres!$A$5:$B$8,2,FALSE),0) -> 0 | L13: =IFERROR(VLOOKUP(E13,Paramètres!$A$5:$B$8,2,FALSE),0) -> 3 | M13: =IFERROR(VLOOKUP(F13,Paramètres!$A$5:$B$8,2,FALSE),0) -> 3 | N13: =IFERROR(VLOOKUP(G13,Paramètres!$D$5:$E$8,2,FALSE),0) -> 0 | O13: =IFERROR(VLOOKUP(H13,Paramètres!$A$5:$B$8,2,FALSE),0) -> 0 | P13: =IFERROR(VLOOKUP(I13,Paramètres!$A$5:$B$8,2,FALSE),0) -> 0 | Q13: =IF(SUM(Paramètres!$G$5:$M$5)=0,"",SUMPRODUCT(Paramètres!$G$5:$M$5,J13,K13,L13,M13,N13,O13,P13)/SUM(Paramètres!$G$5:$M$5)) -> #VALUE!
... A3001: =Réponses_Scoring!A3001 -> 0 | B3001: =Réponses_Scoring!B3001 -> 0 | C3001: =Réponses_Scoring!C3001 -> 0 | D3001: =Réponses_Scoring!D3001 -> 0 | E3001: =Réponses_Scoring!E3001 -> 0 | F3001: =Réponses_Scoring!F3001 -> 0 | G3001: =Réponses_Scoring!G3001 -> 0 | H3001: =Réponses_Scoring!H3001 -> 0 | I3001: =Réponses_Scoring!I3001 -> 0 | J3001: =IFERROR(VLOOKUP(C3001,Paramètres!$A$5:$B$8,2,FALSE),0) -> 0 | K3001: =IFERROR(VLOOKUP(D3001,Paramètres!$A$5:$B$8,2,FALSE),0) -> 0 | L3001: =IFERROR(VLOOKUP(E3001,Paramètres!$A$5:$B$8,2,FALSE),0) -> 0 | M3001: =IFERROR(VLOOKUP(F3001,Paramètres!$A$5:$B$8,2,FALSE),0) -> 0 | N3001: =IFERROR(VLOOKUP(G3001,Paramètres!$D$5:$E$8,2,FALSE),0) -> 0 | O3001: =IFERROR(VLOOKUP(H3001,Paramètres!$A$5:$B$8,2,FALSE),0) -> 0 | P3001: =IFERROR(VLOOKUP(I3001,Paramètres!$A$5:$B$8,2,FALSE),0) -> 0 | Q3001: =IF(SUM(Paramètres!$G$5:$M$5)=0,"",SUMPRODUCT(Paramètres!$G$5:$M$5,J3001,K3001,L3001,M3001,N3001,O3001,P3001)/SUM(Paramètres!$G$5:$M$5)) -> #VALUE!

Sheet Analyse_Domaines
A1: Code domaine | B1: Domaine | C1: Nb sélections (Top10) | D1: Nb Top5 | E1: Score pondéré (Top5) | F1: Consensus Top5 (≈) | G1: Rang (Score pondéré)
A2: D01 | B2: Croissance économique, transformation structurelle et commerce | C2: =SUMIFS(Réponses_Domaines!$C$2:$C$5000,Réponses_Domaines!$B$2:$B$5000,$A2) -> 172 | D2: =COUNTIFS(Réponses_Domaines!$B$2:$B$5000,$A2,Réponses_Domaines!$D$2:$D$5000,"<>") -> 82 | E2: =SUMIFS(Réponses_Domaines!$E$2:$E$5000,Réponses_Domaines!$B$2:$B$5000,$A2) -> 259 | F2: =IFERROR(IF($J$2=0,"",SUMIFS(Aide_Domaines_Pays!$E$2:$E$5000,Aide_Domaines_Pays!$A$2:$A$5000,$A2)/$J$2),"") -> 0.15 | G2: =IFERROR(_xludf.RANK.EQ(E2,$E$2:$E$13,0),"") | I2: Nb pays répondants | J2: =Aide_Pays!B2 -> 200
A3: D02 | B3: Emploi, travail décent et protection sociale | C3: =SUMIFS(Réponses_Domaines!$C$2:$C$5000,Réponses_Domaines!$B$2:$B$5000,$A3) -> 169 | D3: =COUNTIFS(Réponses_Domaines!$B$2:$B$5000,$A3,Réponses_Domaines!$D$2:$D$5000,"<>") -> 81 | E3: =SUMIFS(Réponses_Domaines!$E$2:$E$5000,Réponses_Domaines!$B$2:$B$5000,$A3) -> 229 | F3: =IFERROR(IF($J$2=0,"",SUMIFS(Aide_Domaines_Pays!$E$2:$E$5000,Aide_Domaines_Pays!$A$2:$A$5000,$A3)/$J$2),"") -> 0.15 | G3: =IFERROR(_xludf.RANK.EQ(E3,$E$2:$E$13,0),"")
A4: D03 | B4: Agriculture durable, sécurité alimentaire et nutrition | C4: =SUMIFS(Réponses_Domaines!$C$2:$C$5000,Réponses_Domaines!$B$2:$B$5000,$A4) -> 167 | D4: =COUNTIFS(Réponses_Domaines!$B$2:$B$5000,$A4,Réponses_Domaines!$D$2:$D$5000,"<>") -> 93 | E4: =SUMIFS(Réponses_Domaines!$E$2:$E$5000,Réponses_Domaines!$B$2:$B$5000,$A4) -> 285 | F4: =IFERROR(IF($J$2=0,"",SUMIFS(Aide_Domaines_Pays!$E$2:$E$5000,Aide_Domaines_Pays!$A$2:$A$5000,$A4)/$J$2),"") -> 0.15 | G4: =IFERROR(_xludf.RANK.EQ(E4,$E$2:$E$13,0),"")
A5: D04 | B5: Infrastructures, industrialisation et innovation | C5: =SUMIFS(Réponses_Domaines!$C$2:$C$5000,Réponses_Domaines!$B$2:$B$5000,$A5) -> 166 | D5: =COUNTIFS(Réponses_Domaines!$B$2:$B$5000,$A5,Réponses_Domaines!$D$2:$D$5000,"<>") -> 92 | E5: =SUMIFS(Réponses_Domaines!$E$2:$E$5000,Réponses_Domaines!$B$2:$B$5000,$A5) -> 278 | F5: =IFERROR(IF($J$2=0,"",SUMIFS(Aide_Domaines_Pays!$E$2:$E$5000,Aide_Domaines_Pays!$A$2:$A$5000,$A5)/$J$2),"") -> 0.15 | G5: =IFERROR(_xludf.RANK.EQ(E5,$E$2:$E$13,0),"")
A6: D05 | B6: Inclusion, pauvreté et inégalités | C6: =SUMIFS(Réponses_Domaines!$C$2:$C$5000,Réponses_Domaines!$B$2:$B$5000,$A6) -> 165 | D6: =COUNTIFS(Réponses_Domaines!$B$2:$B$5000,$A6,Réponses_Domaines!$D$2:$D$5000,"<>") -> 79 | E6: =SUMIFS(Réponses_Domaines!$E$2:$E$5000,Réponses_Domaines!$B$2:$B$5000,$A6) -> 245 | F6: =IFERROR(IF($J$2=0,"",SUMIFS(Aide_Domaines_Pays!$E$2:$E$5000,Aide_Domaines_Pays!$A$2:$A$5000,$A6)/$J$2),"") -> 0.15 | G6: =IFERROR(_xludf.RANK.EQ(E6,$E$2:$E$13,0),"")
A7: D06 | B7: Éducation, compétences et capital humain | C7: =SUMIFS(Réponses_Domaines!$C$2:$C$5000,Réponses_Domaines!$B$2:$B$5000,$A7) -> 159 | D7: =COUNTIFS(Réponses_Domaines!$B$2:$B$5000,$A7,Réponses_Domaines!$D$2:$D$5000,"<>") -> 83 | E7: =SUMIFS(Réponses_Domaines!$E$2:$E$5000,Réponses_Domaines!$B$2:$B$5000,$A7) -> 255 | F7: =IFERROR(IF($J$2=0,"",SUMIFS(Aide_Domaines_Pays!$E$2:$E$5000,Aide_Domaines_Pays!$A$2:$A$5000,$A7)/$J$2),"") -> 0.15 | G7: =IFERROR(_xludf.RANK.EQ(E7,$E$2:$E$13,0),"")
A8: D07 | B8: Santé, bien-être et accès universel | C8: =SUMIFS(Réponses_Domaines!$C$2:$C$5000,Réponses_Domaines!$B$2:$B$5000,$A8) -> 159 | D8: =COUNTIFS(Réponses_Domaines!$B$2:$B$5000,$A8,Réponses_Domaines!$D$2:$D$5000,"<>") -> 85 | E8: =SUMIFS(Réponses_Domaines!$E$2:$E$5000,Réponses_Domaines!$B$2:$B$5000,$A8) -> 256 | F8: =IFERROR(IF($J$2=0,"",SUMIFS(Aide_Domaines_Pays!$E$2:$E$5000,Aide_Domaines_Pays!$A$2:$A$5000,$A8)/$J$2),"") -> 0.15 | G8: =IFERROR(_xludf.RANK.EQ(E8,$E$2:$E$13,0),"")
A9: D08 | B9: Égalité des genres et autonomisation | C9: =SUMIFS(Réponses_Domaines!$C$2:$C$5000,Réponses_Domaines!$B$2:$B$5000,$A9) -> 166 | D9: =COUNTIFS(Réponses_Domaines!$B$2:$B$5000,$A9,Réponses_Domaines!$D$2:$D$5000,"<>") -> 73 | E9: =SUMIFS(Réponses_Domaines!$E$2:$E$5000,Réponses_Domaines!$B$2:$B$5000,$A9) -> 203 | F9: =IFERROR(IF($J$2=0,"",SUMIFS(Aide_Domaines_Pays!$E$2:$E$5000,Aide_Domaines_Pays!$A$2:$A$5000,$A9)/$J$2),"") -> 0.15 | G9: =IFERROR(_xludf.RANK.EQ(E9,$E$2:$E$13,0),"")
A10: D09 | B10: Environnement, résilience climatique et villes durables | C10: =SUMIFS(Réponses_Domaines!$C$2:$C$5000,Réponses_Domaines!$B$2:$B$5000,$A10) -> 164 | D10: =COUNTIFS(Réponses_Domaines!$B$2:$B$5000,$A10,Réponses_Domaines!$D$2:$D$5000,"<>") -> 81 | E10: =SUMIFS(Réponses_Domaines!$E$2:$E$5000,Réponses_Domaines!$B$2:$B$5000,$A10) -> 237 | F10: =IFERROR(IF($J$2=0,"",SUMIFS(Aide_Domaines_Pays!$E$2:$E$5000,Aide_Domaines_Pays!$A$2:$A$5000,$A10)/$J$2),"") -> 0.15 | G10: =IFERROR(_xludf.RANK.EQ(E10,$E$2:$E$13,0),"")
A11: D10 | B11: Gouvernance, paix et institutions | C11: =SUMIFS(Réponses_Domaines!$C$2:$C$5000,Réponses_Domaines!$B$2:$B$5000,$A11) -> 171 | D11: =COUNTIFS(Réponses_Domaines!$B$2:$B$5000,$A11,Réponses_Domaines!$D$2:$D$5000,"<>") -> 87 | E11: =SUMIFS(Réponses_Domaines!$E$2:$E$5000,Réponses_Domaines!$B$2:$B$5000,$A11) -> 278 | F11: =IFERROR(IF($J$2=0,"",SUMIFS(Aide_Domaines_Pays!$E$2:$E$5000,Aide_Domaines_Pays!$A$2:$A$5000,$A11)/$J$2),"") -> 0.15 | G11: =IFERROR(_xludf.RANK.EQ(E11,$E$2:$E$13,0),"")
A12: D11 | B12: Économie bleue et gestion des océans | C12: =SUMIFS(Réponses_Domaines!$C$2:$C$5000,Réponses_Domaines!$B$2:$B$5000,$A12) -> 169 | D12: =COUNTIFS(Réponses_Domaines!$B$2:$B$5000,$A12,Réponses_Domaines!$D$2:$D$5000,"<>") -> 77 | E12: =SUMIFS(Réponses_Domaines!$E$2:$E$5000,Réponses_Domaines!$B$2:$B$5000,$A12) -> 229 | F12: =IFERROR(IF($J$2=0,"",SUMIFS(Aide_Domaines_Pays!$E$2:$E$5000,Aide_Domaines_Pays!$A$2:$A$5000,$A12)/$J$2),"") -> 0.15 | G12: =IFERROR(_xludf.RANK.EQ(E12,$E$2:$E$13,0),"")
A13: D12 | B13: Partenariats et financement du développement | C13: =SUMIFS(Réponses_Domaines!$C$2:$C$5000,Réponses_Domaines!$B$2:$B$5000,$A13) -> 173 | D13: =COUNTIFS(Réponses_Domaines!$B$2:$B$5000,$A13,Réponses_Domaines!$D$2:$D$5000,"<>") -> 87 | E13: =SUMIFS(Réponses_Domaines!$E$2:$E$5000,Réponses_Domaines!$B$2:$B$5000,$A13) -> 246 | F13: =IFERROR(IF($J$2=0,"",SUMIFS(Aide_Domaines_Pays!$E$2:$E$5000,Aide_Domaines_Pays!$A$2:$A$5000,$A13)/$J$2),"") -> 0.15 | G13: =IFERROR(_xludf.RANK.EQ(E13,$E$2:$E$13,0),"")

Sheet Analyse_Indicateurs
A1: ID indicateur | B1: Code domaine | C1: Domaine | D1: Indicateur | E1: Source | F1: Nb propositions | G1: Nb pays (approx) | H1: Score global moyen | I1: Consensus pays (approx) | J1: Rang global | K1: Rang dans domaine
A2: D01S01 | B2: =IFERROR(VLOOKUP($A2,Longlist_condensée!$A$2:$D$1000,2,FALSE),"") -> D01 | C2: =IFERROR(VLOOKUP(B2,Référentiel_Domaines!$A$2:$B$13,2,FALSE),"") -> Croissance économique, transformation structurelle et commerce | D2: =IFERROR(VLOOKUP($A2,Longlist_condensée!$A$2:$D$1000,3,FALSE),"") -> Taux de croissance du PIB réel | E2: =IFERROR(VLOOKUP($A2,Longlist_condensée!$A$2:$D$1000,4,FALSE),"") -> UA(STYIP = 2e plan décennal de mise en œuvre) | F2: =COUNTIF(Réponses_Indicateurs!$D$2:$D$5000,$A2) -> 18 | G2: =IFERROR(IF(F2=0,"",SUMIFS(Aide_Indicateurs_Pays!$D$2:$D$5000,Aide_Indicateurs_Pays!$A$2:$A$5000,$A2)),"") -> 11 | H2: =IFERROR(IF(F2=0,"",AVERAGEIF(Codage_Scoring!$B$2:$B$5000,$A2,Codage_Scoring!$Q$2:$Q$5000)),"") | I2: =IFERROR(IF($M$2=0,"",G2/$M$2),"") -> 0.055 | J2: =IFERROR(IF(H2="","",_xludf.RANK.EQ(H2,$H$2:$H$83,0)),"") | K2: =IFERROR(IF(H2="","",1+COUNTIFS($B$2:$B$83,B2,$H$2:$H$83,">"&H2)),"") | L2: Nb pays répondants (unique) : | M2: =Aide_Pays!B2 -> 200
A3: D01S02 | B3: =IFERROR(VLOOKUP($A3,Longlist_condensée!$A$2:$D$1000,2,FALSE),"") -> D01 | C3: =IFERROR(VLOOKUP(B3,Référentiel_Domaines!$A$2:$B$13,2,FALSE),"") -> Croissance économique, transformation structurelle et commerce | D3: =IFERROR(VLOOKUP($A3,Longlist_condensée!$A$2:$D$1000,3,FALSE),"") -> PIB par habitant (USD constant) | E3: =IFERROR(VLOOKUP($A3,Longlist_condensée!$A$2:$D$1000,4,FALSE),"") -> UA (STYIP) | F3: =COUNTIF(Réponses_Indicateurs!$D$2:$D$5000,$A3) -> 16 | G3: =IFERROR(IF(F3=0,"",SUMIFS(Aide_Indicateurs_Pays!$D$2:$D$5000,Aide_Indicateurs_Pays!$A$2:$A$5000,$A3)),"") -> 14 | H3: =IFERROR(IF(F3=0,"",AVERAGEIF(Codage_Scoring!$B$2:$B$5000,$A3,Codage_Scoring!$Q$2:$Q$5000)),"") | I3: =IFERROR(IF($M$2=0,"",G3/$M$2),"") -> 0.07 | J3: =IFERROR(IF(H3="","",_xludf.RANK.EQ(H3,$H$2:$H$83,0)),"") | K3: =IFERROR(IF(H3="","",1+COUNTIFS($B$2:$B$83,B3,$H$2:$H$83,">"&H3)),"")
A4: D01S03 | B4: =IFERROR(VLOOKUP($A4,Longlist_condensée!$A$2:$D$1000,2,FALSE),"") -> D01 | C4: =IFERROR(VLOOKUP(B4,Référentiel_Domaines!$A$2:$B$13,2,FALSE),"") -> Croissance économique, transformation structurelle et commerce | D4: =IFERROR(VLOOKUP($A4,Longlist_condensée!$A$2:$D$1000,3,FALSE),"") -> Part de la Valeur Ajoutée Manufacturière (VAM) dans le PIB | E4: =IFERROR(VLOOKUP($A4,Longlist_condensée!$A$2:$D$1000,4,FALSE),"") -> ODD 9.2 ; UA | F4: =COUNTIF(Réponses_Indicateurs!$D$2:$D$5000,$A4) -> 13 | G4: =IFERROR(IF(F4=0,"",SUMIFS(Aide_Indicateurs_Pays!$D$2:$D$5000,Aide_Indicateurs_Pays!$A$2:$A$5000,$A4)),"") -> 10 | H4: =IFERROR(IF(F4=0,"",AVERAGEIF(Codage_Scoring!$B$2:$B$5000,$A4,Codage_Scoring!$Q$2:$Q$5000)),"") | I4: =IFERROR(IF($M$2=0,"",G4/$M$2),"") -> 0.05 | J4: =IFERROR(IF(H4="","",_xludf.RANK.EQ(H4,$H$2:$H$83,0)),"") | K4: =IFERROR(IF(H4="","",1+COUNTIFS($B$2:$B$83,B4,$H$2:$H$83,">"&H4)),"")
A5: D01S04 | B5: =IFERROR(VLOOKUP($A5,Longlist_condensée!$A$2:$D$1000,2,FALSE),"") -> D01 | C5: =IFERROR(VLOOKUP(B5,Référentiel_Domaines!$A$2:$B$13,2,FALSE),"") -> Croissance économique, transformation structurelle et commerce | D5: =IFERROR(VLOOKUP($A5,Longlist_condensée!$A$2:$D$1000,3,FALSE),"") -> Part des produits de haute technologie dans les exportations manufacturées | E5: =IFERROR(VLOOKUP($A5,Longlist_condensée!$A$2:$D$1000,4,FALSE),"") -> UA (STYIP) | F5: =COUNTIF(Réponses_Indicateurs!$D$2:$D$5000,$A5) -> 14 | G5: =IFERROR(IF(F5=0,"",SUMIFS(Aide_Indicateurs_Pays!$D$2:$D$5000,Aide_Indicateurs_Pays!$A$2:$A$5000,$A5)),"") -> 13 | H5: =IFERROR(IF(F5=0,"",AVERAGEIF(Codage_Scoring!$B$2:$B$5000,$A5,Codage_Scoring!$Q$2:$Q$5000)),"") | I5: =IFERROR(IF($M$2=0,"",G5/$M$2),"") -> 0.065 | J5: =IFERROR(IF(H5="","",_xludf.RANK.EQ(H5,$H$2:$H$83,0)),"") | K5: =IFERROR(IF(H5="","",1+COUNTIFS($B$2:$B$83,B5,$H$2:$H$83,">"&H5)),"")
A6: D01S05 | B6: =IFERROR(VLOOKUP($A6,Longlist_condensée!$A$2:$D$1000,2,FALSE),"") -> D01 | C6: =IFERROR(VLOOKUP(B6,Référentiel_Domaines!$A$2:$B$13,2,FALSE),"") -> Croissance économique, transformation structurelle et commerce | D6: =IFERROR(VLOOKUP($A6,Longlist_condensée!$A$2:$D$1000,3,FALSE),"") -> Part de l'Afrique dans la valeur ajoutée manufacturière mondiale | E6: =IFERROR(VLOOKUP($A6,Longlist_condensée!$A$2:$D$1000,4,FALSE),"") -> UA (STYIP) ; ODD | F6: =COUNTIF(Réponses_Indicateurs!$D$2:$D$5000,$A6) -> 10 | G6: =IFERROR(IF(F6=0,"",SUMIFS(Aide_Indicateurs_Pays!$D$2:$D$5000,Aide_Indicateurs_Pays!$A$2:$A$5000,$A6)),"") -> 9 | H6: =IFERROR(IF(F6=0,"",AVERAGEIF(Codage_Scoring!$B$2:$B$5000,$A6,Codage_Scoring!$Q$2:$Q$5000)),"") | I6: =IFERROR(IF($M$2=0,"",G6/$M$2),"") -> 0.045 | J6: =IFERROR(IF(H6="","",_xludf.RANK.EQ(H6,$H$2:$H$83,0)),"") | K6: =IFERROR(IF(H6="","",1+COUNTIFS($B$2:$B$83,B6,$H$2:$H$83,">"&H6)),"")
A7: D01S06 | B7: =IFERROR(VLOOKUP($A7,Longlist_condensée!$A$2:$D$1000,2,FALSE),"") -> D01 | C7: =IFERROR(VLOOKUP(B7,Référentiel_Domaines!$A$2:$B$13,2,FALSE),"") -> Croissance économique, transformation structurelle et commerce | D7: =IFERROR(VLOOKUP($A7,Longlist_condensée!$A$2:$D$1000,3,FALSE),"") -> Part du commerce intra-africain dans le commerce total | E7: =IFERROR(VLOOKUP($A7,Longlist_condensée!$A$2:$D$1000,4,FALSE),"") -> UA ; BAD | F7: =COUNTIF(Réponses_Indicateurs!$D$2:$D$5000,$A7) -> 19 | G7: =IFERROR(IF(F7=0,"",SUMIFS(Aide_Indicateurs_Pays!$D$2:$D$5000,Aide_Indicateurs_Pays!$A$2:$A$5000,$A7)),"") -> 12 | H7: =IFERROR(IF(F7=0,"",AVERAGEIF(Codage_Scoring!$B$2:$B$5000,$A7,Codage_Scoring!$Q$2:$Q$5000)),"") | I7: =IFERROR(IF($M$2=0,"",G7/$M$2),"") -> 0.06 | J7: =IFERROR(IF(H7="","",_xludf.RANK.EQ(H7,$H$2:$H$83,0)),"") | K7: =IFERROR(IF(H7="","",1+COUNTIFS($B$2:$B$83,B7,$H$2:$H$83,">"&H7)),"")
A8: D01S07 | B8: =IFERROR(VLOOKUP($A8,Longlist_condensée!$A$2:$D$1000,2,FALSE),"") -> D01 | C8: =IFERROR(VLOOKUP(B8,Référentiel_Domaines!$A$2:$B$13,2,FALSE),"") -> Croissance économique, transformation structurelle et commerce | D8: =IFERROR(VLOOKUP($A8,Longlist_condensée!$A$2:$D$1000,3,FALSE),"") -> Indice de diversification économique | E8: =IFERROR(VLOOKUP($A8,Longlist_condensée!$A$2:$D$1000,4,FALSE),"") -> UA (STYIP) | F8: =COUNTIF(Réponses_Indicateurs!$D$2:$D$5000,$A8) -> 13 | G8: =IFERROR(IF(F8=0,"",SUMIFS(Aide_Indicateurs_Pays!$D$2:$D$5000,Aide_Indicateurs_Pays!$A$2:$A$5000,$A8)),"") -> 9 | H8: =IFERROR(IF(F8=0,"",AVERAGEIF(Codage_Scoring!$B$2:$B$5000,$A8,Codage_Scoring!$Q$2:$Q$5000)),"") | I8: =IFERROR(IF($M$2=0,"",G8/$M$2),"") -> 0.045 | J8: =IFERROR(IF(H8="","",_xludf.RANK.EQ(H8,$H$2:$H$83,0)),"") | K8: =IFERROR(IF(H8="","",1+COUNTIFS($B$2:$B$83,B8,$H$2:$H$83,">"&H8)),"")
A9: D01S08 | B9: =IFERROR(VLOOKUP($A9,Longlist_condensée!$A$2:$D$1000,2,FALSE),"") -> D01 | C9: =IFERROR(VLOOKUP(B9,Référentiel_Domaines!$A$2:$B$13,2,FALSE),"") -> Croissance économique, transformation structurelle et commerce | D9: =IFERROR(VLOOKUP($A9,Longlist_condensée!$A$2:$D$1000,3,FALSE),"") -> Contribution directe du tourisme au PIB | E9: =IFERROR(VLOOKUP($A9,Longlist_condensée!$A$2:$D$1000,4,FALSE),"") -> UA (STYIP) | F9: =COUNTIF(Réponses_Indicateurs!$D$2:$D$5000,$A9) -> 19 | G9: =IFERROR(IF(F9=0,"",SUMIFS(Aide_Indicateurs_Pays!$D$2:$D$5000,Aide_Indicateurs_Pays!$A$2:$A$5000,$A9)),"") -> 16 | H9: =IFERROR(IF(F9=0,"",AVERAGEIF(Codage_Scoring!$B$2:$B$5000,$A9,Codage_Scoring!$Q$2:$Q$5000)),"") | I9: =IFERROR(IF($M$2=0,"",G9/$M$2),"") -> 0.08 | J9: =IFERROR(IF(H9="","",_xludf.RANK.EQ(H9,$H$2:$H$83,0)),"") | K9: =IFERROR(IF(H9="","",1+COUNTIFS($B$2:$B$83,B9,$H$2:$H$83,">"&H9)),"")
A10: D01S09 | B10: =IFERROR(VLOOKUP($A10,Longlist_condensée!$A$2:$D$1000,2,FALSE),"") -> D01 | C10: =IFERROR(VLOOKUP(B10,Référentiel_Domaines!$A$2:$B$13,2,FALSE),"") -> Croissance économique, transformation structurelle et commerce | D10: =IFERROR(VLOOKUP($A10,Longlist_condensée!$A$2:$D$1000,3,FALSE),"") -> Formation brute de capital fixe (% PIB) | E10: =IFERROR(VLOOKUP($A10,Longlist_condensée!$A$2:$D$1000,4,FALSE),"") -> BAD | F10: =COUNTIF(Réponses_Indicateurs!$D$2:$D$5000,$A10) -> 20 | G10: =IFERROR(IF(F10=0,"",SUMIFS(Aide_Indicateurs_Pays!$D$2:$D$5000,Aide_Indicateurs_Pays!$A$2:$A$5000,$A10)),"") -> 17 | H10: =IFERROR(IF(F10=0,"",AVERAGEIF(Codage_Scoring!$B$2:$B$5000,$A10,Codage_Scoring!$Q$2:$Q$5000)),"") | I10: =IFERROR(IF($M$2=0,"",G10/$M$2),"") -> 0.085 | J10: =IFERROR(IF(H10="","",_xludf.RANK.EQ(H10,$H$2:$H$83,0)),"") | K10: =IFERROR(IF(H10="","",1+COUNTIFS($B$2:$B$83,B10,$H$2:$H$83,">"&H10)),"")
A11: D01S10 | B11: =IFERROR(VLOOKUP($A11,Longlist_condensée!$A$2:$D$1000,2,FALSE),"") -> D01 | C11: =IFERROR(VLOOKUP(B11,Référentiel_Domaines!$A$2:$B$13,2,FALSE),"") -> Croissance économique, transformation structurelle et commerce | D11: =IFERROR(VLOOKUP($A11,Longlist_condensée!$A$2:$D$1000,3,FALSE),"") -> Pays commerçant sous le régime ZLECA | E11: =IFERROR(VLOOKUP($A11,Longlist_condensée!$A$2:$D$1000,4,FALSE),"") -> UA | F11: =COUNTIF(Réponses_Indicateurs!$D$2:$D$5000,$A11) -> 14 | G11: =IFERROR(IF(F11=0,"",SUMIFS(Aide_Indicateurs_Pays!$D$2:$D$5000,Aide_Indicateurs_Pays!$A$2:$A$5000,$A11)),"") -> 10 | H11: =IFERROR(IF(F11=0,"",AVERAGEIF(Codage_Scoring!$B$2:$B$5000,$A11,Codage_Scoring!$Q$2:$Q$5000)),"") | I11: =IFERROR(IF($M$2=0,"",G11/$M$2),"") -> 0.05 | J11: =IFERROR(IF(H11="","",_xludf.RANK.EQ(H11,$H$2:$H$83,0)),"") | K11: =IFERROR(IF(H11="","",1+COUNTIFS($B$2:$B$83,B11,$H$2:$H$83,">"&H11)),"")
A12: D02S11 | B12: =IFERROR(VLOOKUP($A12,Longlist_condensée!$A$2:$D$1000,2,FALSE),"") -> D02 | C12: =IFERROR(VLOOKUP(B12,Référentiel_Domaines!$A$2:$B$13,2,FALSE),"") -> Emploi, travail décent et protection sociale | D12: =IFERROR(VLOOKUP($A12,Longlist_condensée!$A$2:$D$1000,3,FALSE),"") -> Taux de chômage (total, jeunes, femmes) | E12: =IFERROR(VLOOKUP($A12,Longlist_condensée!$A$2:$D$1000,4,FALSE),"") -> UA (STYIP) | F12: =COUNTIF(Réponses_Indicateurs!$D$2:$D$5000,$A12) -> 25 | G12: =IFERROR(IF(F12=0,"",SUMIFS(Aide_Indicateurs_Pays!$D$2:$D$5000,Aide_Indicateurs_Pays!$A$2:$A$5000,$A12)),"") -> 20 | H12: =IFERROR(IF(F12=0,"",AVERAGEIF(Codage_Scoring!$B$2:$B$5000,$A12,Codage_Scoring!$Q$2:$Q$5000)),"") | I12: =IFERROR(IF($M$2=0,"",G12/$M$2),"") -> 0.1 | J12: =IFERROR(IF(H12="","",_xludf.RANK.EQ(H12,$H$2:$H$83,0)),"") | K12: =IFERROR(IF(H12="","",1+COUNTIFS($B$2:$B$83,B12,$H$2:$H$83,">"&H12)),"")
A13: D02S12 | B13: =IFERROR(VLOOKUP($A13,Longlist_condensée!$A$2:$D$1000,2,FALSE),"") -> D02 | C13: =IFERROR(VLOOKUP(B13,Référentiel_Domaines!$A$2:$B$13,2,FALSE),"") -> Emploi, travail décent et protection sociale | D13: =IFERROR(VLOOKUP($A13,Longlist_condensée!$A$2:$D$1000,3,FALSE),"") -> Nombre d'emplois créés (dont jeunes) | E13: =IFERROR(VLOOKUP($A13,Longlist_condensée!$A$2:$D$1000,4,FALSE),"") -> BAD | F13: =COUNTIF(Réponses_Indicateurs!$D$2:$D$5000,$A13) -> 22 | G13: =IFERROR(IF(F13=0,"",SUMIFS(Aide_Indicateurs_Pays!$D$2:$D$5000,Aide_Indicateurs_Pays!$A$2:$A$5000,$A13)),"") -> 15 | H13: =IFERROR(IF(F13=0,"",AVERAGEIF(Codage_Scoring!$B$2:$B$5000,$A13,Codage_Scoring!$Q$2:$Q$5000)),"") | I13: =IFERROR(IF($M$2=0,"",G13/$M$2),"") -> 0.075 | J13: =IFERROR(IF(H13="","",_xludf.RANK.EQ(H13,$H$2:$H$83,0)),"") | K13: =IFERROR(IF(H13="","",1+COUNTIFS($B$2:$B$83,B13,$H$2:$H$83,">"&H13)),"")
A14: D02S13 | B14: =IFERROR(VLOOKUP($A14,Longlist_condensée!$A$2:$D$1000,2,FALSE),"") -> D02 | C14: =IFERROR(VLOOKUP(B14,Référentiel_Domaines!$A$2:$B$13,2,FALSE),"") -> Emploi, travail décent et protection sociale | D14: =IFERROR(VLOOKUP($A14,Longlist_condensée!$A$2:$D$1000,3,FALSE),"") -> Taux de jeunes NEET (15-24 ans) | E14: =IFERROR(VLOOKUP($A14,Longlist_condensée!$A$2:$D$1000,4,FALSE),"") -> ODD 8.6 ; UA | F14: =COUNTIF(Réponses_Indicateurs!$D$2:$D$5000,$A14) -> 27 | G14: =IFERROR(IF(F14=0,"",SUMIFS(Aide_Indicateurs_Pays!$D$2:$D$5000,Aide_Indicateurs_Pays!$A$2:$A$5000,$A14)),"") -> 20 | H14: =IFERROR(IF(F14=0,"",AVERAGEIF(Codage_Scoring!$B$2:$B$5000,$A14,Codage_Scoring!$Q$2:$Q$5000)),"") | I14: =IFERROR(IF($M$2=0,"",G14/$M$2),"") -> 0.1 | J14: =IFERROR(IF(H14="","",_xludf.RANK.EQ(H14,$H$2:$H$83,0)),"") | K14: =IFERROR(IF(H14="","",1+COUNTIFS($B$2:$B$83,B14,$H$2:$H$83,">"&H14)),"")
... A73: D11S71 | B73: =IFERROR(VLOOKUP($A73,Longlist_condensée!$A$2:$D$1000,2,FALSE),"") -> D11 | C73: =IFERROR(VLOOKUP(B73,Référentiel_Domaines!$A$2:$B$13,2,FALSE),"") -> Économie bleue et gestion des océans | D73: =IFERROR(VLOOKUP($A73,Longlist_condensée!$A$2:$D$1000,3,FALSE),"") -> Emplois liés à l'économie bleue | E73: =IFERROR(VLOOKUP($A73,Longlist_condensée!$A$2:$D$1000,4,FALSE),"") -> UA (ABES) | F73: =COUNTIF(Réponses_Indicateurs!$D$2:$D$5000,$A73) -> 24 | G73: =IFERROR(IF(F73=0,"",SUMIFS(Aide_Indicateurs_Pays!$D$2:$D$5000,Aide_Indicateurs_Pays!$A$2:$A$5000,$A73)),"") -> 14 | H73: =IFERROR(IF(F73=0,"",AVERAGEIF(Codage_Scoring!$B$2:$B$5000,$A73,Codage_Scoring!$Q$2:$Q$5000)),"") | I73: =IFERROR(IF($M$2=0,"",G73/$M$2),"") -> 0.07 | J73: =IFERROR(IF(H73="","",_xludf.RANK.EQ(H73,$H$2:$H$83,0)),"") | K73: =IFERROR(IF(H73="","",1+COUNTIFS($B$2:$B$83,B73,$H$2:$H$83,">"&H73)),"")
A74: D11S72 | B74: =IFERROR(VLOOKUP($A74,Longlist_condensée!$A$2:$D$1000,2,FALSE),"") -> D11 | C74: =IFERROR(VLOOKUP(B74,Référentiel_Domaines!$A$2:$B$13,2,FALSE),"") -> Économie bleue et gestion des océans | D74: =IFERROR(VLOOKUP($A74,Longlist_condensée!$A$2:$D$1000,3,FALSE),"") -> Aires marines protégées (% zones territoriales) | E74: =IFERROR(VLOOKUP($A74,Longlist_condensée!$A$2:$D$1000,4,FALSE),"") -> ODD 14.5 ; UA | F74: =COUNTIF(Réponses_Indicateurs!$D$2:$D$5000,$A74) -> 23 | G74: =IFERROR(IF(F74=0,"",SUMIFS(Aide_Indicateurs_Pays!$D$2:$D$5000,Aide_Indicateurs_Pays!$A$2:$A$5000,$A74)),"") -> 17 | H74: =IFERROR(IF(F74=0,"",AVERAGEIF(Codage_Scoring!$B$2:$B$5000,$A74,Codage_Scoring!$Q$2:$Q$5000)),"") | I74: =IFERROR(IF($M$2=0,"",G74/$M$2),"") -> 0.085 | J74: =IFERROR(IF(H74="","",_xludf.RANK.EQ(H74,$H$2:$H$83,0)),"") | K74: =IFERROR(IF(H74="","",1+COUNTIFS($B$2:$B$83,B74,$H$2:$H$83,">"&H74)),"") | M74: =Aide_Pays!B74 -> 0
A75: D11S73 | B75: =IFERROR(VLOOKUP($A75,Longlist_condensée!$A$2:$D$1000,2,FALSE),"") -> D11 | C75: =IFERROR(VLOOKUP(B75,Référentiel_Domaines!$A$2:$B$13,2,FALSE),"") -> Économie bleue et gestion des océans | D75: =IFERROR(VLOOKUP($A75,Longlist_condensée!$A$2:$D$1000,3,FALSE),"") -> Pénétration de l'énergie bleue | E75: =IFERROR(VLOOKUP($A75,Longlist_condensée!$A$2:$D$1000,4,FALSE),"") -> UA (STYIP) | F75: =COUNTIF(Réponses_Indicateurs!$D$2:$D$5000,$A75) -> 27 | G75: =IFERROR(IF(F75=0,"",SUMIFS(Aide_Indicateurs_Pays!$D$2:$D$5000,Aide_Indicateurs_Pays!$A$2:$A$5000,$A75)),"") -> 17 | H75: =IFERROR(IF(F75=0,"",AVERAGEIF(Codage_Scoring!$B$2:$B$5000,$A75,Codage_Scoring!$Q$2:$Q$5000)),"") | I75: =IFERROR(IF($M$2=0,"",G75/$M$2),"") -> 0.085 | J75: =IFERROR(IF(H75="","",_xludf.RANK.EQ(H75,$H$2:$H$83,0)),"") | K75: =IFERROR(IF(H75="","",1+COUNTIFS($B$2:$B$83,B75,$H$2:$H$83,">"&H75)),"") | M75: =Aide_Pays!B75 -> 0
A76: D11S74 | B76: =IFERROR(VLOOKUP($A76,Longlist_condensée!$A$2:$D$1000,2,FALSE),"") -> D11 | C76: =IFERROR(VLOOKUP(B76,Référentiel_Domaines!$A$2:$B$13,2,FALSE),"") -> Économie bleue et gestion des océans | D76: =IFERROR(VLOOKUP($A76,Longlist_condensée!$A$2:$D$1000,3,FALSE),"") -> Stocks de poissons durables | E76: =IFERROR(VLOOKUP($A76,Longlist_condensée!$A$2:$D$1000,4,FALSE),"") -> ODD 14.4 | F76: =COUNTIF(Réponses_Indicateurs!$D$2:$D$5000,$A76) -> 24 | G76: =IFERROR(IF(F76=0,"",SUMIFS(Aide_Indicateurs_Pays!$D$2:$D$5000,Aide_Indicateurs_Pays!$A$2:$A$5000,$A76)),"") -> 17 | H76: =IFERROR(IF(F76=0,"",AVERAGEIF(Codage_Scoring!$B$2:$B$5000,$A76,Codage_Scoring!$Q$2:$Q$5000)),"") | I76: =IFERROR(IF($M$2=0,"",G76/$M$2),"") -> 0.085 | J76: =IFERROR(IF(H76="","",_xludf.RANK.EQ(H76,$H$2:$H$83,0)),"") | K76: =IFERROR(IF(H76="","",1+COUNTIFS($B$2:$B$83,B76,$H$2:$H$83,">"&H76)),"") | M76: =Aide_Pays!B76 -> 0
A77: D11S75 | B77: =IFERROR(VLOOKUP($A77,Longlist_condensée!$A$2:$D$1000,2,FALSE),"") -> D11 | C77: =IFERROR(VLOOKUP(B77,Référentiel_Domaines!$A$2:$B$13,2,FALSE),"") -> Économie bleue et gestion des océans | D77: =IFERROR(VLOOKUP($A77,Longlist_condensée!$A$2:$D$1000,3,FALSE),"") -> Indicateur D11S75 (à préciser) | E77: =IFERROR(VLOOKUP($A77,Longlist_condensée!$A$2:$D$1000,4,FALSE),"") -> À préciser | F77: =COUNTIF(Réponses_Indicateurs!$D$2:$D$5000,$A77) -> 40 | G77: =IFERROR(IF(F77=0,"",SUMIFS(Aide_Indicateurs_Pays!$D$2:$D$5000,Aide_Indicateurs_Pays!$A$2:$A$5000,$A77)),"") -> 22 | H77: =IFERROR(IF(F77=0,"",AVERAGEIF(Codage_Scoring!$B$2:$B$5000,$A77,Codage_Scoring!$Q$2:$Q$5000)),"") | I77: =IFERROR(IF($M$2=0,"",G77/$M$2),"") -> 0.11 | J77: =IFERROR(IF(H77="","",_xludf.RANK.EQ(H77,$H$2:$H$83,0)),"") | K77: =IFERROR(IF(H77="","",1+COUNTIFS($B$2:$B$83,B77,$H$2:$H$83,">"&H77)),"") | M77: =Aide_Pays!B77 -> 0
A78: D12S75 | B78: =IFERROR(VLOOKUP($A78,Longlist_condensée!$A$2:$D$1000,2,FALSE),"") -> D12 | C78: =IFERROR(VLOOKUP(B78,Référentiel_Domaines!$A$2:$B$13,2,FALSE),"") -> Partenariats et financement du développement | D78: =IFERROR(VLOOKUP($A78,Longlist_condensée!$A$2:$D$1000,3,FALSE),"") -> Ratio recettes fiscales / PIB | E78: =IFERROR(VLOOKUP($A78,Longlist_condensée!$A$2:$D$1000,4,FALSE),"") -> UA (STYIP) ; BAD | F78: =COUNTIF(Réponses_Indicateurs!$D$2:$D$5000,$A78) -> 0 | G78: =IFERROR(IF(F78=0,"",SUMIFS(Aide_Indicateurs_Pays!$D$2:$D$5000,Aide_Indicateurs_Pays!$A$2:$A$5000,$A78)),"") | H78: =IFERROR(IF(F78=0,"",AVERAGEIF(Codage_Scoring!$B$2:$B$5000,$A78,Codage_Scoring!$Q$2:$Q$5000)),"") | I78: =IFERROR(IF($M$2=0,"",G78/$M$2),"") | J78: =IFERROR(IF(H78="","",_xludf.RANK.EQ(H78,$H$2:$H$83,0)),"") | K78: =IFERROR(IF(H78="","",1+COUNTIFS($B$2:$B$83,B78,$H$2:$H$83,">"&H78)),"") | M78: =Aide_Pays!B78 -> 0
A79: D12S76 | B79: =IFERROR(VLOOKUP($A79,Longlist_condensée!$A$2:$D$1000,2,FALSE),"") -> D12 | C79: =IFERROR(VLOOKUP(B79,Référentiel_Domaines!$A$2:$B$13,2,FALSE),"") -> Partenariats et financement du développement | D79: =IFERROR(VLOOKUP($A79,Longlist_condensée!$A$2:$D$1000,3,FALSE),"") -> Flux financiers illicites (% PIB) | E79: =IFERROR(VLOOKUP($A79,Longlist_condensée!$A$2:$D$1000,4,FALSE),"") -> UA (STYIP) | F79: =COUNTIF(Réponses_Indicateurs!$D$2:$D$5000,$A79) -> 34 | G79: =IFERROR(IF(F79=0,"",SUMIFS(Aide_Indicateurs_Pays!$D$2:$D$5000,Aide_Indicateurs_Pays!$A$2:$A$5000,$A79)),"") -> 17 | H79: =IFERROR(IF(F79=0,"",AVERAGEIF(Codage_Scoring!$B$2:$B$5000,$A79,Codage_Scoring!$Q$2:$Q$5000)),"") | I79: =IFERROR(IF($M$2=0,"",G79/$M$2),"") -> 0.085 | J79: =IFERROR(IF(H79="","",_xludf.RANK.EQ(H79,$H$2:$H$83,0)),"") | K79: =IFERROR(IF(H79="","",1+COUNTIFS($B$2:$B$83,B79,$H$2:$H$83,">"&H79)),"") | M79: =Aide_Pays!B79 -> 0
A80: D12S77 | B80: =IFERROR(VLOOKUP($A80,Longlist_condensée!$A$2:$D$1000,2,FALSE),"") -> D12 | C80: =IFERROR(VLOOKUP(B80,Référentiel_Domaines!$A$2:$B$13,2,FALSE),"") -> Partenariats et financement du développement | D80: =IFERROR(VLOOKUP($A80,Longlist_condensée!$A$2:$D$1000,3,FALSE),"") -> Part du budget financé par impôts nationaux | E80: =IFERROR(VLOOKUP($A80,Longlist_condensée!$A$2:$D$1000,4,FALSE),"") -> ODD 17.1 ; UA | F80: =COUNTIF(Réponses_Indicateurs!$D$2:$D$5000,$A80) -> 39 | G80: =IFERROR(IF(F80=0,"",SUMIFS(Aide_Indicateurs_Pays!$D$2:$D$5000,Aide_Indicateurs_Pays!$A$2:$A$5000,$A80)),"") -> 21 | H80: =IFERROR(IF(F80=0,"",AVERAGEIF(Codage_Scoring!$B$2:$B$5000,$A80,Codage_Scoring!$Q$2:$Q$5000)),"") | I80: =IFERROR(IF($M$2=0,"",G80/$M$2),"") -> 0.105 | J80: =IFERROR(IF(H80="","",_xludf.RANK.EQ(H80,$H$2:$H$83,0)),"") | K80: =IFERROR(IF(H80="","",1+COUNTIFS($B$2:$B$83,B80,$H$2:$H$83,">"&H80)),"") | M80: =Aide_Pays!B80 -> 0
